<?xml version="1.0" encoding="UTF-8"?>
<!-- Generated by org.testng.reporters.JUnitReportReporter -->
<testsuite hostname="DESKTOP-ECUBRGD" failures="1" tests="1" name="Handle_Exception_TestNG.testException" time="6.542" errors="0" timestamp="13 Aug 2020 15:03:39 GMT">
  <testcase classname="Handle_Exception_TestNG.testException" name="testException1" time="6.542">
    <failure message="
Expected exception java.io.IOException but got org.testng.TestException: 
Method testException.testException1()[pri:0, instance:Handle_Exception_TestNG.testException@3b0090a4] should have thrown an exception of class java.io.IOException" type="org.testng.TestException">
      <![CDATA[org.testng.TestException: 
Expected exception java.io.IOException but got org.testng.TestException: 
Method testException.testException1()[pri:0, instance:Handle_Exception_TestNG.testException@3b0090a4] should have thrown an exception of class java.io.IOException
	at org.testng.internal.Invoker.handleInvocationResults(Invoker.java:1497)
	at org.testng.internal.Invoker.invokeTestMethods(Invoker.java:1245)
	at org.testng.internal.TestMethodWorker.invokeTestMethods(TestMethodWorker.java:127)
	at org.testng.internal.TestMethodWorker.run(TestMethodWorker.java:111)
	at org.testng.TestRunner.privateRun(TestRunner.java:767)
	at org.testng.TestRunner.run(TestRunner.java:617)
	at org.testng.SuiteRunner.runTest(SuiteRunner.java:334)
	at org.testng.SuiteRunner.runSequentially(SuiteRunner.java:329)
	at org.testng.SuiteRunner.privateRun(SuiteRunner.java:291)
	at org.testng.SuiteRunner.run(SuiteRunner.java:240)
	at org.testng.SuiteRunnerWorker.runSuite(SuiteRunnerWorker.java:52)
	at org.testng.SuiteRunnerWorker.run(SuiteRunnerWorker.java:86)
	at org.testng.TestNG.runSuitesSequentially(TestNG.java:1198)
	at org.testng.TestNG.runSuitesLocally(TestNG.java:1123)
	at org.testng.TestNG.run(TestNG.java:1031)
	at org.testng.remote.AbstractRemoteTestNG.run(AbstractRemoteTestNG.java:114)
	at org.testng.remote.RemoteTestNG.initAndRun(RemoteTestNG.java:251)
	at org.testng.remote.RemoteTestNG.main(RemoteTestNG.java:77)
Caused by: org.testng.TestException: 
Method testException.testException1()[pri:0, instance:Handle_Exception_TestNG.testException@3b0090a4] should have thrown an exception of class java.io.IOException
	at org.testng.internal.Invoker.handleInvocationResults(Invoker.java:1512)
	at org.testng.internal.Invoker.invokeMethod(Invoker.java:754)
	at org.testng.internal.Invoker.invokeTestMethod(Invoker.java:901)
	at org.testng.internal.Invoker.invokeTestMethods(Invoker.java:1231)
	... 16 more
]]>
    </failure>
  </testcase> <!-- testException1 -->
</testsuite> <!-- Handle_Exception_TestNG.testException -->
